<?xml version='1.0'?>

<robot name="my_robot" xmlns:xacro="http://www.ros.org/wiki/xacro">

  <link name="robot_footprint"></link>

  <joint name="robot_footprint_joint" type="fixed">
    <origin xyz="0 0 0" rpy="0 0 0" />
    <parent link="robot_footprint"/>
    <child link="chassis" />
  </joint>

  <link name='chassis'>
    <pose>0 0 0.1 0 0 0</pose>

    <inertial>
      <mass value="15.0"/>
      <origin xyz="0.0 0 0" rpy=" 0 0 0"/>
      <inertia
          ixx="0.1" ixy="0" ixz="0"
          iyy="0.1" iyz="0"
          izz="0.1"
      />
    </inertial>

    <collision name='collision'>
      <origin xyz="0 0 0" rpy=" 0 0 0"/> 
      <geometry>
        <box size="0.7 .2 .1"/>
      </geometry>
    </collision>

    <visual name='chassis_visual'>
      <origin xyz="0 0 0" rpy=" 0 0 0"/>
      <geometry>
        <box size="0.7 .2 .1"/>
      </geometry>
    </visual>


    <collision name='back_caster_collision'>
      <origin xyz="-0.15 0 -0.05" rpy=" 0 0 0"/>
      <geometry>
        <sphere radius="0.0499"/>
      </geometry>
    </collision>

    <visual name='back_caster_visual'>
      <origin xyz="-0.15 0 -0.05" rpy=" 0 0 0"/>
      <geometry>
        <sphere radius="0.05"/>
      </geometry>
    </visual>

    <collision name='front_caster_collision'>
      <origin xyz="0.15 0 -0.05" rpy=" 0 0 0"/>
      <geometry>
        <sphere radius="0.0499"/>
      </geometry>
    </collision>

    <visual name='front_caster_visual'>
      <origin xyz="0.15 0 -0.05" rpy=" 0 0 0"/>
      <geometry>
        <sphere radius="0.05"/>
      </geometry>
    </visual>

  </link>

  <link name="left_front_wheel">
	  <inertial>
		  <mass value="5.0" />
		  <origin xyz="0 0 0" rpy="0 1.5707 1.5707" />
		  <inertia ixx="0.1" ixy="0" ixz="0"
    			    iyy="0.1" iyz="0"
    			    izz="0.1"/>
	  </inertial>
	  <visual>
		  <origin xyz="0 0 0" rpy="0 1.5707 1.5707" />
		  <geometry>
			  <cylinder radius="0.1" length="0.05" />
		  </geometry>
	  </visual>
	  <collision>
		  <origin xyz="0 0 0" rpy="0 1.5707 1.5707" />
		  <geometry>
			  <cylinder radius="0.1" length="0.05" />
		  </geometry>
	  </collision>
  </link>
  <joint type="continuous" name="left_front_wheel_hinge">
    <origin xyz="0 0.15 0" rpy="0 0 0"/>
    <child link="left_front_wheel"/>
    <parent link="chassis"/>
    <axis xyz="0 1 0" rpy="0 0 0"/>
    <limit effort="10000" velocity="1000"/>
    <dynamics damping="1.0" friction="1.0"/>
  </joint>
  <link name="left_rear_wheel">
	  <inertial>
		  <mass value="5.0" />
		  <origin xyz="0 0 0" rpy="0 1.5707 1.5707" />
		  <inertia ixx="0.1" ixy="0" ixz="0"
    			    iyy="0.1" iyz="0"
    			    izz="0.1"/>
	  </inertial>
	  <visual>
		  <origin xyz="0 0 0" rpy="0 1.5707 1.5707" />
		  <geometry>
			  <cylinder radius="0.1" length="0.05" />
		  </geometry>
	  </visual>
	  <collision>
		  <origin xyz="0 0 0" rpy="0 1.5707 1.5707" />
		  <geometry>
			  <cylinder radius="0.1" length="0.05" />
		  </geometry>
	  </collision>
  </link>
  <joint type="continuous" name="left_rear_wheel_hinge">
    <origin xyz="-0.3 0.15 0" rpy="0 0 0"/>
    <child link="left_rear_wheel"/>
    <parent link="chassis"/>
    <axis xyz="0 1 0" rpy="0 0 0"/>
    <limit effort="10000" velocity="1000"/>
    <dynamics damping="1.0" friction="1.0"/>
  </joint>
  <link name="right_front_wheel">
	  <inertial>
		  <mass value="5.0"/>
		  <origin xyz="0 0 0" rpy="0 1.5707 1.5707"/>
		  <inertia ixx="0.1" ixy="0" ixz="0" iyy="0.1" iyz="0" izz="0.1"  />
	  </inertial>
	  <visual>
		  <origin xyz="0 0 0" rpy="0 1.5707 1.5707" />
		  <geometry>
			  <cylinder radius="0.1" length="0.05" />
		  </geometry>
	  </visual>
	  <collision>
		  <origin xyz="0 0 0" rpy="0 1.5707 1.5707" />
		  <geometry>
			  <cylinder radius="0.1" length="0.05" />
		  </geometry>
	  </collision>
  </link>
  <joint type="continuous" name="right_front_wheel_hinge">
    <origin xyz="0 -0.15 0" rpy="0 0 0"/>
    <child link="right_front_wheel"/>
    <parent link="chassis"/>
    <axis xyz="0 1 0" rpy="0 0 0"/>
    <limit effort="10000" velocity="1000"/>
    <dynamics damping="1.0" friction="1.0"/>
  </joint>
  <link name="right_rear_wheel">
	  <inertial>
		  <mass value="5.0"/>
		  <origin xyz="0 0 0" rpy="0 1.5707 1.5707"/>
		  <inertia ixx="0.1" ixy="0" ixz="0" iyy="0.1" iyz="0" izz="0.1"  />
	  </inertial>
	  <visual>
		  <origin xyz="0 0 0" rpy="0 1.5707 1.5707" />
		  <geometry>
			  <cylinder radius="0.1" length="0.05" />
		  </geometry>
	  </visual>
	  <collision>
		  <origin xyz="0 0 0" rpy="0 1.5707 1.5707" />
		  <geometry>
			  <cylinder radius="0.1" length="0.05" />
		  </geometry>
	  </collision>
  </link>
  <joint type="continuous" name="right_rear_wheel_hinge">
    <origin xyz="-0.3 -0.15 0" rpy="0 0 0"/>
    <child link="right_rear_wheel"/>
    <parent link="chassis"/>
    <axis xyz="0 1 0" rpy="0 0 0"/>
    <limit effort="10000" velocity="1000"/>
    <dynamics damping="1.0" friction="1.0"/>
  </joint>
  <!--link name='test'>
    <inertial>
      <mass value="0.1"/>
      <origin xyz="0 0 0" rpy="0 0 0"/>
      <inertia
    <inertial>
      <mass value="0.1"/>
      <origin xyz="0 0 0" rpy="0 0 0"/>
      <inertia
        ixx="1e-6" ixy="0" ixz="0"
        iyy="1e-6" iyz="0"
        izz="1e-6"
      />
    </inertial>
    <collision name='collision'>
      <origin xyz="0 0 0" rpy="0 0 0"/>
      <geometry>
        <box size=".05 .05 .05"/>
      </geometry>
    </collision>
    <visual name='chassis_visual'>
      <origin xyz="0 0 0" rpy="0 0 0"/>
      <geometry>
        <box size=".05 .05 .05"/>
      </geometry>
    </visual>
    <box_inertia sizeX="0.05" sizeY="0.05" sizeZ="0.05" mass="0.1">
      <origin xyz="0 0 0" rpy="0 0 0" />
    </box_inertia>
  </link-->
  <!--link name="test">
	  <inertial>
		  <mass value="0.1"/>
		  <origin xyz="0 0 0" rpy="0 0 0"/>
      <inertia
        ixx="1e-6" ixy="0" ixz="0"
        iyy="1e-6" iyz="0"
        izz="1e-6"
      />
	  </inertial>
	  <visual>
		  <origin xyz="0 0 0" rpy="0 0 0"/>
		  <geometry>
			  <box size="0.05 0.05 0.05"/>
		  </geometry>
	  </visual>
	  <collision>
		  <origin xyz="0 0 0" rpy="0 0 0"/>
		  <geometry>
			  <box size="0.05 0.05 0.05"/>
		  </geometry>
	  </collision>
  </link-->
  <!--link name="camera_link">
	  <inertial>
		  <mass value="0.1"/>
		  <origin xyz="0 0 0" rpy="0 0 0"/>
		  <inertia  ixx="1e-6" ixy="0" ixz="0" iyy="1e-6" iyz="0" izz="1e-6" />
	  </inertial>
	  <visual>
		  <origin xyz="0 0 0" rpy="0 0 0" />
		  <geometry>
			  <box size="0.05 0.05 0.05" />
		  </geometry>
	  </visual>
	  <collision>
		  <origin xyz="0 0 0" rpy="0 0 0" />
		  <geometry>
			  <box size="0.05 0.05 0.05" />
		  </geometry>
	  </collision>
  </link-->
  <!--joint type="fixed" name="camera_joint">
	  <axis xyz="0 0 1" rpy="0 0 0"/>
	  <origin xyz="0.2 0 0" rpy="0 0 0" />
	  <parent link="chassis" />
	  <child link="test" />
  </joint-->
	  <xacro:property name="cameraSize" value="0.05"/>
  <xacro:property name="cameraMass" value="0.1"/>
  <!-- camera -->
	    <link name="camera">
    <collision>
      <origin xyz="0 0 0" rpy="0 0 0"/>
      <geometry>
        <box size="${cameraSize} ${cameraSize} ${cameraSize}"/>
      </geometry>
    </collision>

    <visual>
      <origin xyz="0 0 0" rpy="0 0 0"/>
      <geometry>
        <box size="${cameraSize} ${cameraSize} ${cameraSize}"/>
      </geometry>
      <!--material name="green"/-->
    </visual>

    <inertial>
      <mass value="${cameraMass}" />
      <origin xyz="0 0 0" rpy="0 0 0"/>
      <box_inertia m="${cameraMass}" x="${cameraSize}" y="${cameraSize}" z="${cameraSize}" />
      <inertia ixx="1e-6" ixy="0" ixz="0" iyy="1e-6" iyz="0" izz="1e-6" />
    </inertial>
  </link>

  <joint name="camera_joint" type="fixed">
    <axis xyz="0 1 0" />
    <origin xyz="0.35 0 0" rpy="0 0 0"/>
    <parent link="chassis"/>
    <child link="camera"/>
  </joint>
	  <joint name="hokuyo_joint" type="fixed">
    <axis xyz="0 1 0" />
    <origin xyz=".15 0 .1" rpy="0 0 0"/>
    <parent link="chassis"/>
    <child link="hokuyo"/>
  </joint>

  <!-- Hokuyo Laser -->
  <link name="hokuyo">
    <collision>
      <origin xyz="0 0 0" rpy="0 0 0"/>
      <geometry>
    <box size="0.1 0.1 0.1"/>
      </geometry>
    </collision>

    <visual>
      <origin xyz="0 0 0" rpy="0 0 0"/>
      <geometry>
        <mesh filename="package://my_robot/meshes/hokuyo.dae"/>
      </geometry>
    </visual>

    <inertial>
      <mass value="1e-5" />
      <origin xyz="0 0 0" rpy="0 0 0"/>
      <inertia ixx="1e-6" ixy="0" ixz="0" iyy="1e-6" iyz="0" izz="1e-6" />
    </inertial>
  </link>
	  <gazebo reference="left_front_wheel">
    <material>Gazebo/Green</material>
</gazebo>
	  <gazebo reference="left_rear_wheel">
    <material>Gazebo/Green</material>
</gazebo>
	<gazebo reference="right_front_wheel">
    <material>Gazebo/Yellow</material>
</gazebo>
	<gazebo reference="right_rear_wheel">
    <material>Gazebo/Yellow</material>
</gazebo>
	<gazebo reference="camera">
    <material>Gazebo/Red</material>
</gazebo>
	<gazebo reference="chassis">
    <material>Gazebo/Blue</material>
</gazebo>
	<xacro:include filename="$(find my_robot)/urdf/my_robot.gazebo" />
</robot>
